starting worker pid=20388 on localhost:11628 at 15:38:51.081
starting worker pid=20160 on localhost:11628 at 15:38:51.109
Warning messages:
1: In FUN(X[[i]], ...) :
  Try Error occured for 50.6155871629178,50.7305012642986,50.7287650360066,50.715675977728,50.7281194352528,50.6996580627099,50.7103218829639,50.6990147378629,50.7288593712128,-1.22309244729702,-1.16011767804923,-1.165208098041,-1.30358264507789,-1.15571839240039,-1.28237004532161,-1.3076064908069,-1.28555355415503,-1.17181106215918 50.6604954602709,50.6985428540881,50.71237568177,50.6305497097685,50.70468763193,50.6379377588033,50.6331414598419,50.6791945008666,50.7489997981845,-1.15946695472241,-1.42878983750453,-1.11238187653755,-1.18904326817978,-1.49206294615627,-1.17368947656466,-1.17620800588495,-1.51666203877554,-1.28034032711103 Error in otp_plan_internal(otpcon = otpcon, fromPlace = fromPlace[x, ],  : 
  could not find function "otp_plan_internal"

2: Warning messages:
In FUN(X[[i]], ...) :1:  Try Error occured for 50.6155871629178,50.7305012642986,50.7287650360066,50.715675977728,50.7281194352528,50.6996580627099,50.7103218829639,50.6990147378629,50.7288593712128,-1.22309244729702,-1.16011767804923,-1.165208098041,-1.30358264507789,-1.15571839240039,-1.28237004532161,-1.3076064908069,-1.28555355415503,-1.17181106215918 50.6604954602709,50.6985428540881,50.71237568177,50.6305497097685,50.70468763193,50.6379377588033,50.6331414598419,50.6791945008666,50.7489997981845,-1.15946695472241,-1.42878983750453,-1.11238187653755,-1.18904326817978,-1.49206294615627,-1.17368947656466,-1.17620800588495,-1.51666203877554,-1.28034032711103 Error in otp_plan_internal(otpcon = otpcon, fromPlace = fromPlace[x, ],  : 
  could not find function "otp_plan_internal"

In FUN(X[[i]], ...) :
  Try Error occured for 50.6155871629178,50.7305012642986,50.7287650360066,50.715675977728,50.7281194352528,50.6996580627099,50.7103218829639,50.6990147378629,50.7288593712128,-1.22309244729702,-1.16011767804923,-1.165208098041,-1.30358264507789,-1.15571839240039,-1.28237004532161,-1.3076064908069,-1.28555355415503,-1.17181106215918 50.6604954602709,50.6985428540881,50.71237568177,50.6305497097685,50.70468763193,50.6379377588033,50.6331414598419,50.6791945008666,50.7489997981845,-1.15946695472241,-1.42878983750453,-1.11238187653755,-1.18904326817978,-1.49206294615627,-1.17368947656466,-1.17620800588495,-1.51666203877554,-1.28034032711103 Error in otp_plan_internal(otpcon = otpcon, fromPlace = fromPlace[x, ],  : 
  could not find function "otp_plan_internal"


 2:  Try Error occured for 50.6155871629178,50.7305012642986,50.7287650360066,50.715675977728,50.7281194352528,50.6996580627099,50.7103218829639,50.6990147378629,50.7288593712128,-1.22309244729702,-1.16011767804923,-1.165208098041,-1.30358264507789,-1.15571839240039,-1.28237004532161,-1.3076064908069,-1.28555355415503,-1.17181106215918 50.6604954602709,50.6985428540881,50.71237568177,50.6305497097685,50.70468763193,50.6379377588033,50.6331414598419,50.6791945008666,50.7489997981845,-1.15946695472241,-1.42878983750453,-1.11238187653755,-1.18904326817978,-1.49206294615627,-1.17368947656466,-1.17620800588495,-1.51666203877554,-1.28034032711103 Error in otp_plan_internal(otpcon = otpcon, fromPlace = fromPlace[x, ],  : 
  could not find function "otp_plan_internal"

4: In FUN(X[[i]], ...) :
 In FUN(X[[i]], ...) : Try Error occured for 50.6155871629178,50.7305012642986,50.7287650360066,50.715675977728,50.7281194352528,50.6996580627099,50.7103218829639,50.6990147378629,50.7288593712128,-1.22309244729702,-1.16011767804923,-1.165208098041,-1.30358264507789,-1.15571839240039,-1.28237004532161,-1.3076064908069,-1.28555355415503,-1.17181106215918 50.6604954602709,50.6985428540881,50.71237568177,50.6305497097685,50.70468763193,50.6379377588033,50.6331414598419,50.6791945008666,50.7489997981845,-1.15946695472241,-1.42878983750453,-1.11238187653755,-1.18904326817978,-1.49206294615627,-1.17368947656466,-1.17620800588495,-1.51666203877554,-1.28034032711103 Error in otp_plan_internal(otpcon = otpcon, fromPlace = fromPlace[x, ],  : 
  could not find function "otp_plan_internal"

3: 
 In FUN(X[[i]], ...) :
  Try Error occured for 50.6155871629178,50.7305012642986,50.7287650360066,50.715675977728,50.7281194352528,50.6996580627099,50.7103218829639,50.6990147378629,50.7288593712128,-1.22309244729702,-1.16011767804923,-1.165208098041,-1.30358264507789,-1.15571839240039,-1.28237004532161,-1.3076064908069,-1.28555355415503,-1.17181106215918 50.6604954602709,50.6985428540881,50.71237568177,50.6305497097685,50.70468763193,50.6379377588033,50.6331414598419,50.6791945008666,50.7489997981845,-1.15946695472241,-1.42878983750453,-1.11238187653755,-1.18904326817978,-1.49206294615627,-1.17368947656466,-1.17620800588495,-1.51666203877554,-1.28034032711103 Error in otp_plan_internal(otpcon = otpcon, fromPlace = fromPlace[x, ],  : 
  could not find function "otp_plan_internal"

 Try Error occured for 50.6155871629178,50.7305012642986,50.7287650360066,50.715675977728,50.7281194352528,50.6996580627099,50.7103218829639,50.6990147378629,50.7288593712128,-1.22309244729702,-1.16011767804923,-1.165208098041,-1.30358264507789,-1.15571839240039,-1.28237004532161,-1.3076064908069,-1.28555355415503,-1.17181106215918 50.6604954602709,50.6985428540881,50.71237568177,50.6305497097685,50.70468763193,50.6379377588033,50.6331414598419,50.6791945008666,50.7489997981845,-1.15946695472241,-1.42878983750453,-1.11238187653755,-1.18904326817978,-1.49206294615627,-1.17368947656466,-1.17620800588495,-1.51666203877554,-1.28034032711103 Error in otp_plan_internal(otpcon = otpcon, fromPlace = fromPlace[x, ],  : 
  could not find function "otp_plan_internal"

5: In FUN(X[[i]], ...) :
  Try Error occured for 50.6155871629178,50.7305012642986,50.7287650360066,50.715675977728,50.7281194352528,50.6996580627099,50.7103218829639,50.6990147378629,50.7288593712128,-1.22309244729702,-1.16011767804923,-1.165208098041,-1.30358264507789,-1.15571839240039,-1.28237004532161,-1.3076064908069,-1.28555355415503,-1.17181106215918 50.6604954602709,50.6985428540881,50.71237568177,50.6305497097685,50.70468763193,50.6379377588033,50.6331414598419,50.6791945008666,50.7489997981845,-1.15946695472241,-1.42878983750453,-1.11238187653755,-1.18904326817978,-1.49206294615627,-1.17368947656466,-1.17620800588495,-1.51666203877554,-1.28034032711103 Error in otp_plan_internal(otpcon = otpcon, fromPlace = fromPlace[x, ],  : 
  could not find function "otp_plan_internal"

6: In FUN(X[[i]], ...) :
  Try Error occured for 50.6155871629178,50.7305012642986,50.7287650360066,50.715675977728,50.7281194352528,50.6996580627099,50.7103218829639,50.6990147378629,50.7288593712128,-1.22309244729702,-1.16011767804923,-1.165208098041,-1.30358264507789,-1.15571839240039,-1.28237004532161,-1.3076064908069,-1.28555355415503,-1.17181106215918 50.6604954602709,50.6985428540881,50.71237568177,50.6305497097685,50.70468763193,50.6379377588033,50.6331414598419,50.6791945008666,50.7489997981845,-1.15946695472241,-1.42878983750453,-1.11238187653755,-1.18904326817978,-1.49206294615627,-1.17368947656466,-1.17620800588495,-1.51666203877554,-1.28034032711103 Error in otp_plan_internal(otpcon = otpcon, fromPlace = fromPlace[x, ],  : 
  could not find function "otp_plan_internal"

starting worker pid=6580 on localhost:11320 at 15:59:36.363
starting worker pid=17052 on localhost:11320 at 15:59:36.371
Warning message:
replacing previous import 'vctrs::data_frame' by 'tibble::data_frame' when loading 'dplyr' 
Warning message:
replacing previous import 'vctrs::data_frame' by 'tibble::data_frame' when loading 'dplyr' 
starting worker pid=5916 on localhost:11320 at 16:00:32.137
starting worker pid=13452 on localhost:11320 at 16:00:32.155
Warning message:
replacing previous import 'vctrs::data_frame' by 'tibble::data_frame' when loading 'dplyr' 
Warning message:
replacing previous import 'vctrs::data_frame' by 'tibble::data_frame' when loading 'dplyr' 
starting worker pid=17656 on localhost:11320 at 16:00:36.587
starting worker pid=2284 on localhost:11320 at 16:00:36.591
Warning message:
replacing previous import 'vctrs::data_frame' by 'tibble::data_frame' when loading 'dplyr' 
Warning message:
replacing previous import 'vctrs::data_frame' by 'tibble::data_frame' when loading 'dplyr' 
